(venv) PS C:\Users\Prashant\PycharmProjects\seleniumTestProject> pytest main.py
=============================================================================== test session starts ===============================================================================
platform win32 -- Python 3.11.3, pytest-7.3.0, pluggy-1.0.0
rootdir: C:\Users\Prashant\PycharmProjects\seleniumTestProject
plugins: bdd-6.1.1
collected 1 item

main.py
INTERNALERROR> Traceback (most recent call last):
INTERNALERROR>   File "C:\Users\Prashant\PycharmProjects\seleniumTestProject\venv\Lib\site-packages\_pytest\main.py", line 269, in wrap_session
INTERNALERROR>     session.exitstatus = doit(config, session) or 0
INTERNALERROR>                          ^^^^^^^^^^^^^^^^^^^^^
INTERNALERROR>   File "C:\Users\Prashant\PycharmProjects\seleniumTestProject\venv\Lib\site-packages\_pytest\main.py", line 323, in _main
INTERNALERROR>     config.hook.pytest_runtestloop(session=session)
INTERNALERROR>   File "C:\Users\Prashant\PycharmProjects\seleniumTestProject\venv\Lib\site-packages\pluggy\_hooks.py", line 265, in __call__
INTERNALERROR>     return self._hookexec(self.name, self.get_hookimpls(), kwargs, firstresult)
INTERNALERROR>            ^^^^^^^^^^^^^^^^^^^^^^^^^^^^^^^^^^^^^^^^^^^^^^^^^^^^^^^^^^^^^^^^^^^^
INTERNALERROR>   File "C:\Users\Prashant\PycharmProjects\seleniumTestProject\venv\Lib\site-packages\pluggy\_manager.py", line 80, in _hookexec
INTERNALERROR>     return self._inner_hookexec(hook_name, methods, kwargs, firstresult)
INTERNALERROR>            ^^^^^^^^^^^^^^^^^^^^^^^^^^^^^^^^^^^^^^^^^^^^^^^^^^^^^^^^^^^^^
INTERNALERROR>   File "C:\Users\Prashant\PycharmProjects\seleniumTestProject\venv\Lib\site-packages\pluggy\_callers.py", line 60, in _multicall
INTERNALERROR>     return outcome.get_result()
INTERNALERROR>            ^^^^^^^^^^^^^^^^^^^^
INTERNALERROR>   File "C:\Users\Prashant\PycharmProjects\seleniumTestProject\venv\Lib\site-packages\pluggy\_result.py", line 60, in get_result
INTERNALERROR>     raise ex[1].with_traceback(ex[2])
INTERNALERROR>   File "C:\Users\Prashant\PycharmProjects\seleniumTestProject\venv\Lib\site-packages\pluggy\_callers.py", line 39, in _multicall
INTERNALERROR>     res = hook_impl.function(*args)
INTERNALERROR>           ^^^^^^^^^^^^^^^^^^^^^^^^^
INTERNALERROR>   File "C:\Users\Prashant\PycharmProjects\seleniumTestProject\venv\Lib\site-packages\_pytest\main.py", line 348, in pytest_runtestloop
INTERNALERROR>     item.config.hook.pytest_runtest_protocol(item=item, nextitem=nextitem)
INTERNALERROR>   File "C:\Users\Prashant\PycharmProjects\seleniumTestProject\venv\Lib\site-packages\pluggy\_hooks.py", line 265, in __call__
INTERNALERROR>     return self._hookexec(self.name, self.get_hookimpls(), kwargs, firstresult)
INTERNALERROR>            ^^^^^^^^^^^^^^^^^^^^^^^^^^^^^^^^^^^^^^^^^^^^^^^^^^^^^^^^^^^^^^^^^^^^
INTERNALERROR>   File "C:\Users\Prashant\PycharmProjects\seleniumTestProject\venv\Lib\site-packages\pluggy\_manager.py", line 80, in _hookexec
INTERNALERROR>     return self._inner_hookexec(hook_name, methods, kwargs, firstresult)
INTERNALERROR>            ^^^^^^^^^^^^^^^^^^^^^^^^^^^^^^^^^^^^^^^^^^^^^^^^^^^^^^^^^^^^^
INTERNALERROR>   File "C:\Users\Prashant\PycharmProjects\seleniumTestProject\venv\Lib\site-packages\pluggy\_callers.py", line 60, in _multicall
INTERNALERROR>     return outcome.get_result()
INTERNALERROR>            ^^^^^^^^^^^^^^^^^^^^
INTERNALERROR>   File "C:\Users\Prashant\PycharmProjects\seleniumTestProject\venv\Lib\site-packages\pluggy\_result.py", line 60, in get_result
INTERNALERROR>     raise ex[1].with_traceback(ex[2])
INTERNALERROR>   File "C:\Users\Prashant\PycharmProjects\seleniumTestProject\venv\Lib\site-packages\pluggy\_callers.py", line 39, in _multicall
INTERNALERROR>     res = hook_impl.function(*args)
INTERNALERROR>           ^^^^^^^^^^^^^^^^^^^^^^^^^
INTERNALERROR>   File "C:\Users\Prashant\PycharmProjects\seleniumTestProject\venv\Lib\site-packages\_pytest\runner.py", line 114, in pytest_runtest_protocol
INTERNALERROR>     runtestprotocol(item, nextitem=nextitem)
INTERNALERROR>   File "C:\Users\Prashant\PycharmProjects\seleniumTestProject\venv\Lib\site-packages\_pytest\runner.py", line 133, in runtestprotocol
INTERNALERROR>     reports.append(call_and_report(item, "call", log))
INTERNALERROR>                    ^^^^^^^^^^^^^^^^^^^^^^^^^^^^^^^^^^
INTERNALERROR>   File "C:\Users\Prashant\PycharmProjects\seleniumTestProject\venv\Lib\site-packages\_pytest\runner.py", line 224, in call_and_report
INTERNALERROR>     report: TestReport = hook.pytest_runtest_makereport(item=item, call=call)
INTERNALERROR>                          ^^^^^^^^^^^^^^^^^^^^^^^^^^^^^^^^^^^^^^^^^^^^^^^^^^^^
INTERNALERROR>   File "C:\Users\Prashant\PycharmProjects\seleniumTestProject\venv\Lib\site-packages\pluggy\_hooks.py", line 265, in __call__
INTERNALERROR>     return self._hookexec(self.name, self.get_hookimpls(), kwargs, firstresult)
INTERNALERROR>            ^^^^^^^^^^^^^^^^^^^^^^^^^^^^^^^^^^^^^^^^^^^^^^^^^^^^^^^^^^^^^^^^^^^^
INTERNALERROR>   File "C:\Users\Prashant\PycharmProjects\seleniumTestProject\venv\Lib\site-packages\pluggy\_manager.py", line 80, in _hookexec
INTERNALERROR>     return self._inner_hookexec(hook_name, methods, kwargs, firstresult)
INTERNALERROR>            ^^^^^^^^^^^^^^^^^^^^^^^^^^^^^^^^^^^^^^^^^^^^^^^^^^^^^^^^^^^^^
INTERNALERROR>   File "C:\Users\Prashant\PycharmProjects\seleniumTestProject\venv\Lib\site-packages\pluggy\_callers.py", line 55, in _multicall
INTERNALERROR>     gen.send(outcome)
INTERNALERROR>   File "C:\Users\Prashant\PycharmProjects\seleniumTestProject\venv\Lib\site-packages\_pytest\skipping.py", line 266, in pytest_runtest_makereport
INTERNALERROR>     rep = outcome.get_result()
INTERNALERROR>           ^^^^^^^^^^^^^^^^^^^^
INTERNALERROR>   File "C:\Users\Prashant\PycharmProjects\seleniumTestProject\venv\Lib\site-packages\pluggy\_result.py", line 60, in get_result
INTERNALERROR>     raise ex[1].with_traceback(ex[2])
INTERNALERROR>   File "C:\Users\Prashant\PycharmProjects\seleniumTestProject\venv\Lib\site-packages\pluggy\_callers.py", line 39, in _multicall
INTERNALERROR>     res = hook_impl.function(*args)
INTERNALERROR>           ^^^^^^^^^^^^^^^^^^^^^^^^^
INTERNALERROR>   File "C:\Users\Prashant\PycharmProjects\seleniumTestProject\venv\Lib\site-packages\_pytest\runner.py", line 368, in pytest_runtest_makereport
INTERNALERROR>     return TestReport.from_item_and_call(item, call)
INTERNALERROR>            ^^^^^^^^^^^^^^^^^^^^^^^^^^^^^^^^^^^^^^^^^
INTERNALERROR>   File "C:\Users\Prashant\PycharmProjects\seleniumTestProject\venv\Lib\site-packages\_pytest\reports.py", line 363, in from_item_and_call
INTERNALERROR>     longrepr = item.repr_failure(excinfo)
INTERNALERROR>                ^^^^^^^^^^^^^^^^^^^^^^^^^^
INTERNALERROR>   File "C:\Users\Prashant\PycharmProjects\seleniumTestProject\venv\Lib\site-packages\_pytest\python.py", line 1833, in repr_failure
INTERNALERROR>     return self._repr_failure_py(excinfo, style=style)
INTERNALERROR>            ^^^^^^^^^^^^^^^^^^^^^^^^^^^^^^^^^^^^^^^^^^^
INTERNALERROR>   File "C:\Users\Prashant\PycharmProjects\seleniumTestProject\venv\Lib\site-packages\_pytest\nodes.py", line 484, in _repr_failure_py
INTERNALERROR>     return excinfo.getrepr(
INTERNALERROR>            ^^^^^^^^^^^^^^^^
INTERNALERROR>   File "C:\Users\Prashant\PycharmProjects\seleniumTestProject\venv\Lib\site-packages\_pytest\_code\code.py", line 671, in getrepr
INTERNALERROR>     return fmt.repr_excinfo(self)
INTERNALERROR>            ^^^^^^^^^^^^^^^^^^^^^^
INTERNALERROR>   File "C:\Users\Prashant\PycharmProjects\seleniumTestProject\venv\Lib\site-packages\_pytest\_code\code.py", line 987, in repr_excinfo
INTERNALERROR>     return ExceptionChainRepr(repr_chain)
INTERNALERROR>            ^^^^^^^^^^^^^^^^^^^^^^^^^^^^^^
INTERNALERROR>   File "C:\Users\Prashant\PycharmProjects\seleniumTestProject\venv\Lib\site-packages\_pytest\_code\code.py", line 1039, in __init__
INTERNALERROR>     reprtraceback=chain[-1][0],
INTERNALERROR>                   ~~~~~^^^^
INTERNALERROR> IndexError: list index out of range
